Workbook
Name Slicer_category: #N/A
Name Slicer_gender: #N/A

Sheet Raw Data
A1: order_id | B1: customer_id | C1: age | D1: product_id | E1: country | F1: signup_date | G1: last_purchase_date | H1: cancellations_count | I1: subscription_status | J1: order_date | K1: unit_price | L1: quantity | M1: purchase_frequency | N1: preferred_category | O1: product_name | P1: category | Q1: gender
A2: ORD5000 | B2: CUST1000 | C2: 39 | D2: PROD200 | E2: Canada | F2: 44378 | G2: 2/21/2023 | H2: 0 | I2: active | J2: 8/20/2024 | K2: 78.21 | L2: 5 | M2: 37 | N2: Sports | O2: Football | P2: Sports | Q2: Female
A3: ORD5001 | B3: CUST1001 | C3: 61 | D3: PROD201 | E3: USA | F3: 10/19/2020 | G3: 44420 | H3: 0 | I3: active | J3: 7/17/2025 | K3: 64.02 | L3: 8 | M3: 35 | N3: Sports | O3: Refrigerator | P3: Home | Q3: Female
A4: ORD5002 | B4: CUST1002 | C4: 26 | D4: PROD202 | E4: Pakistan | F4: 45205 | G4: 45025 | H4: 3 | I4: cancelled | J4: 45994 | K4: 604.14 | L4: 2 | M4: 44 | N4: Electronics | O4: Hoodie | P4: Clothing | Q4: Female
A5: ORD5003 | B5: CUST1003 | C5: 54 | D5: PROD203 | E5: India | F5: 7/30/2023 | G5: 2/20/2024 | H5: 4 | I5: paused | J5: 9/19/2024 | K5: 84.66 | L5: 4 | M5: 1 | N5: Sports | O5: Conditioner | P5: Beauty | Q5: Male
A6: ORD5004 | B6: CUST1004 | C6: 50 | D6: PROD204 | E6: India | F6: 44086 | G6: 9/14/2024 | H6: 0 | I6: active | J6: 45512 | K6: 62.66 | L6: 7 | M6: 35 | N6: Sports | O6: Smartwatch | P6: Electronics | Q6: Male
A7: ORD5005 | B7: CUST1005 | C7: 46 | D7: PROD205 | E7: Pakistan | F7: 5/16/2023 | G7: 8/13/2025 | H7: 2 | I7: active | J7: 10/14/2024 | K7: 221.61 | L7: 8 | M7: 16 | N7: Electronics | O7: Hoodie | P7: Clothing | Q7: Male
A8: ORD5006 | B8: CUST1006 | C8: 29 | D8: PROD206 | E8: Germany | F8: 45203 | G8: 7/15/2025 | H8: 1 | I8: active | J8: 45415 | K8: 175.74 | L8: 4 | M8: 7 | N8: Clothing | O8: Tablet | P8: Electronics | Q8: Female
A9: ORD5007 | B9: CUST1007 | C9: 24 | D9: PROD207 | E9: UK | F9: 44872 | G9: 12/31/2024 | H9: 2 | I9: active | J9: 3/21/2025 | K9: 9.56 | L9: 5 | M9: 34 | N9: Clothing | O9: Jacket | P9: Clothing | Q9: Female
A10: ORD5008 | B10: CUST1008 | C10: 53 | D10: PROD208 | E10: Pakistan | F10: 4/25/2021 | G10: 12/26/2024 | H10: 4 | I10: paused | J10: 12/14/2023 | K10: 1525.8 | L10: 1 | M10: 32 | N10: Electronics | O10: Nail Polish | P10: Beauty | Q10: Female
A11: ORD5009 | B11: CUST1009 | C11: 38 | D11: PROD209 | E11: Germany | F11: 44451 | G11: 11/29/2024 | H11: 2 | I11: active | J11: 12/24/2021 | K11: 337.24 | L11: 4 | M11: 6 | N11: Clothing | O11: Camera | P11: Electronics | Q11: Male
A12: ORD5010 | B12: CUST1010 | C12: 41 | D12: PROD210 | E12: UK | F12: 43931 | G12: 44600 | H12: 2 | I12: active | J12: 11/23/2023 | K12: 203.05 | L12: 6 | M12: 38 | N12: Home | O12: Dumbbells | P12: Sports | Q12: Female
A13: ORD5011 | B13: CUST1011 | C13: 24 | D13: PROD211 | E13: Canada | F13: 44897 | G13: 45994 | H13: 1 | I13: active | J13: 5/30/2025 | K13: 940.17 | L13: 1 | M13: 24 | N13: Beauty | O13: Headphones | P13: Electronics | Q13: Female
A14: ORD5012 | B14: CUST1012 | C14: 39 | D14: PROD212 | E14: Canada | F14: 12/20/2020 | G14: 1/16/2023 | H14: 2 | I14: active | J14: 44385 | K14: 168.79 | L14: 9 | M14: 36 | N14: Beauty | O14: Vacuum Cleaner | P14: Home | Q14: Female
A15: ORD5013 | B15: CUST1013 | C15: 61 | D15: PROD213 | E15: USA | F15: 2/19/2021 | G15: 45547 | H15: 3 | I15: active | J15: 1/26/2024 | K15: 236.77 | L15: 8 | M15: 5 | N15: Sports | O15: Perfume | P15: Beauty | Q15: Female
A16: ORD5014 | B16: CUST1014 | C16: 64 | D16: PROD214 | E16: UK | F16: 2/27/2021 | G16: 4/24/2025 | H16: 1 | I16: active | J16: 45089 | K16: 130.32 | L16: 6 | M16: 20 | N16: Clothing | O16: Cycling Helmet | P16: Sports | Q16: Female
A17: ORD5015 | B17: CUST1015 | C17: 28 | D17: PROD215 | E17: UK | F17: 12/31/2021 | G17: 11/15/2023 | H17: 5 | I17: cancelled | J17: 11/30/2024 | K17: 333.99 | L17: 3 | M17: 27 | N17: Home | O17: Face Wash | P17: Beauty | Q17: Female
A18: ORD5016 | B18: CUST1016 | C18: 34 | D18: PROD216 | E18: USA | F18: 44354 | G18: 45696 | H18: 1 | I18: active | J18: 6/19/2024 | K18: 1875.08 | L18: 1 | M18: 31 | N18: Sports | O18: Football | P18: Sports | Q18: Female
A19: ORD5017 | B19: CUST1017 | C19: 22 | D19: PROD217 | E19: Pakistan | F19: 9/14/2021 | G19: 45390 | H19: 0 | I19: cancelled | J19: 1/27/2024 | K19: 211.24 | L19: 6 | M19: 18 | N19: Electronics | O19: Cricket Bat | P19: Sports | Q19: Male
A20: ORD5018 | B20: CUST1018 | C20: 42 | D20: PROD218 | E20: USA | F20: 5/25/2023 | G20: 45901 | H20: 5 | I20: paused | J20: 8/13/2025 | K20: 1702.39 | L20: 1 | M20: 14 | N20: Clothing | O20: Sneakers | P20: Clothing | Q20: Male
A21: ORD5019 | B21: CUST1019 | C21: 51 | D21: PROD219 | E21: India | F21: 9/14/2022 | G21: 8/13/2025 | H21: 0 | I21: paused | J21: 10/27/2024 | K21: 199.58 | L21: 8 | M21: 41 | N21: Clothing | O21: Refrigerator | P21: Home | Q21: Female
A22: ORD5020 | B22: CUST1020 | C22: 64 | D22: PROD220 | E22: Canada | F22: 3/13/2022 | G22: 1/23/2024 | H22: 4 | I22: active | J22: 44717 | K22: 242.03 | L22: 6 | M22: 2 | N22: Electronics | O22: Cricket Bat | P22: Sports | Q22: Female
A23: ORD5021 | B23: CUST1021 | C23: 52 | D23: PROD221 | E23: Germany | F23: 44229 | G23: 6/20/2022 | H23: 1 | I23: paused | J23: 8/20/2024 | K23: 50.78 | L23: 7 | M23: 9 | N23: Home | O23: Dress | P23: Clothing | Q23: Male
A24: ORD5022 | B24: CUST1022 | C24: 28 | D24: PROD222 | E24: Germany | F24: 44810 | G24: 44689 | H24: 2 | I24: active | J24: 45445 | K24: 89.87 | L24: 6 | M24: 39 | N24: Home | O24: Smartphone | P24: Electronics | Q24: Female
A25: ORD5023 | B25: CUST1023 | C25: 25 | D25: PROD223 | E25: Germany | F25: 44291 | G25: 45967 | H25: 5 | I25: active | J25: 45968 | K25: 52.34 | L25: 8 | M25: 16 | N25: Electronics | O25: Camera | P25: Electronics | Q25: Male
A26: ORD5024 | B26: CUST1024 | C26: 45 | D26: PROD224 | E26: Germany | F26: 4/14/2022 | G26: 1/29/2023 | H26: 2 | I26: active | J26: 5/21/2024 | K26: 232.67 | L26: 3 | M26: 20 | N26: Clothing | O26: Lipstick | P26: Beauty | Q26: Male
A27: ORD5025 | B27: CUST1025 | C27: 49 | D27: PROD225 | E27: India | F27: 44388 | G27: 44810 | H27: 3 | I27: cancelled | J27: 9/26/2022 | K27: 142.89 | L27: 5 | M27: 40 | N27: Clothing | O27: Sneakers | P27: Clothing | Q27: Male
A28: ORD5026 | B28: CUST1026 | C28: 27 | D28: PROD226 | E28: Germany | F28: 5/15/2023 | G28: 45782 | H28: 0 | I28: paused | J28: 8/26/2024 | K28: 44.69 | L28: 7 | M28: 28 | N28: Beauty | O28: T-Shirt | P28: Clothing | Q28: Male
A29: ORD5027 | B29: CUST1027 | C29: 69 | D29: PROD227 | E29: Pakistan | F29: 3/23/2021 | G29: 2/25/2022 | H29: 4 | I29: cancelled | J29: 11/13/2024 | K29: 139.3 | L29: 7 | M29: 42 | N29: Clothing | O29: Tennis Racket | P29: Sports | Q29: Male
A30: ORD5028 | B30: CUST1028 | C30: 66 | D30: PROD228 | E30: India | F30: 44233 | G30: 45720 | H30: 1 | I30: active | J30: 1/17/2022 | K30: 149.65 | L30: 8 | M30: 45 | N30: Electronics | O30: Sofa | P30: Home | Q30: Male
A31: ORD5029 | B31: CUST1029 | C31: 43 | D31: PROD229 | E31: Canada | F31: 8/22/2020 | G31: 3/22/2024 | H31: 3 | I31: cancelled | J31: 44355 | K31: 157.1 | L31: 6 | M31: 14 | N31: Electronics | O31: Laptop | P31: Electronics | Q31: Female
A32: ORD5030 | B32: CUST1030 | C32: 18 | D32: PROD230 | E32: Germany | F32: 4/19/2021 | G32: 44202 | H32: 5 | I32: active | J32: 45019 | K32: 182.53 | L32: 9 | M32: 24 | N32: Clothing | O32: Basketball | P32: Sports | Q32: Male
A33: ORD5031 | B33: CUST1031 | C33: 37 | D33: PROD231 | E33: Canada | F33: 8/19/2021 | G33: 7/22/2023 | H33: 4 | I33: paused | J33: 45482 | K33: 31.95 | L33: 1 | M33: 9 | N33: Home | O33: Dress | P33: Clothing | Q33: Male
A34: ORD5032 | B34: CUST1032 | C34: 52 | D34: PROD232 | E34: Germany | F34: 44441 | G34: 7/27/2021 | H34: 0 | I34: cancelled | J34: 45210 | K34: 804.77 | L34: 2 | M34: 26 | N34: Beauty | O34: Cycling Helmet | P34: Sports | Q34: Female
A35: ORD5033 | B35: CUST1033 | C35: 50 | D35: PROD233 | E35: Canada | F35: 3/25/2022 | G35: 9/25/2022 | H35: 5 | I35: active | J35: 44690 | K35: 332.38 | L35: 5 | M35: 29 | N35: Home | O35: Shirt | P35: Clothing | Q35: Male
A36: ORD5034 | B36: CUST1034 | C36: 49 | D36: PROD234 | E36: UK | F36: 2/26/2021 | G36: 4/22/2025 | H36: 5 | I36: active | J36: 10/18/2021 | K36: 1292.65 | L36: 1 | M36: 12 | N36: Electronics | O36: Cricket Bat | P36: Sports | Q36: Female
A37: ORD5035 | B37: CUST1035 | C37: 48 | D37: PROD235 | E37: India | F37: 44507 | G37: 11/23/2023 | H37: 3 | I37: active | J37: 45357 | K37: 36.39 | L37: 7 | M37: 24 | N37: Electronics | O37: Tablet | P37: Electronics | Q37: Female
A38: ORD5036 | B38: CUST1036 | C38: 42 | D38: PROD236 | E38: UK | F38: 44993 | G38: 1/14/2024 | H38: 0 | I38: paused | J38: 9/22/2024 | K38: 79.19 | L38: 7 | M38: 13 | N38: Home | O38: Camera | P38: Electronics | Q38: Male
A39: ORD5037 | B39: CUST1037 | C39: 66 | D39: PROD237 | E39: India | F39: 3/25/2023 | G39: 5/16/2023 | H39: 3 | I39: active | J39: 12/29/2024 | K39: 94.06 | L39: 4 | M39: 48 | N39: Sports | O39: Blender | P39: Home | Q39: Male
A40: ORD5038 | B40: CUST1038 | C40: 25 | D40: PROD238 | E40: Pakistan | F40: 2/17/2022 | G40: 6/29/2023 | H40: 3 | I40: paused | J40: 3/13/2022 | K40: 786.48 | L40: 2 | M40: 11 | N40: Sports | O40: Basketball | P40: Sports | Q40: Female
...

Sheet Data
A1: order_id | B1: customer_id | C1: age | D1: product_id | E1: country | F1: signup_date | G1: last_purchase_date | H1: cancellations_count | I1: subscription_status | J1: order_date | K1: unit_price | L1: quantity | M1: purchase_frequency | N1: preferred_category | O1: product_name | P1: category | Q1: gender | R1: gross_revenue | S1: preference_alignment | T1: age_group | U1: Customer_Lifetime_Value_Tier | V1: dormancy_risk
A2: ORD5000 | B2: CUST1000 | C2: 39 | D2: PROD200 | E2: Canada | F2: 44378 | G2: 2/21/2023 | H2: 0 | I2: active | J2: 8/20/2024 | K2: $78.21 | L2: 5 | M2: 37 | N2: Sports | O2: Football | P2: Sports | Q2: Female | R2: 391.05 | S2: Aligned | T2: 35-49 Gen X | U2: High Value Tier | V2: Stable
A3: ORD5001 | B3: CUST1001 | C3: 61 | D3: PROD201 | E3: USA | F3: 10/19/2020 | G3: 44420 | H3: 0 | I3: active | J3: 7/17/2025 | K3: $64.02 | L3: 8 | M3: 35 | N3: Sports | O3: Refrigerator | P3: Home | Q3: Female | R3: 512.16 | S3: Misaligned | T3: 50-64 Boomers | U3: High Value Tier | V3: Stable
A4: ORD5002 | B4: CUST1002 | C4: 26 | D4: PROD202 | E4: Pakistan | F4: 45205 | G4: 45025 | H4: 3 | I4: cancelled | J4: 45994 | K4: $604.14 | L4: 2 | M4: 44 | N4: Electronics | O4: Hoodie | P4: Clothing | Q4: Female | R4: 1208.28 | S4: Misaligned | T4: 25-34 Millennials | U4: High Value Tier | V4: Stable
A5: ORD5003 | B5: CUST1003 | C5: 54 | D5: PROD203 | E5: India | F5: 7/30/2023 | G5: 2/20/2024 | H5: 4 | I5: paused | J5: 9/19/2024 | K5: $84.66 | L5: 4 | M5: 1 | N5: Sports | O5: Conditioner | P5: Beauty | Q5: Male | R5: 338.64 | S5: Misaligned | T5: 50-64 Boomers | U5: Value Tier | V5: Elevated Risk
A6: ORD5004 | B6: CUST1004 | C6: 50 | D6: PROD204 | E6: India | F6: 44086 | G6: 9/14/2024 | H6: 0 | I6: active | J6: 45512 | K6: $62.66 | L6: 7 | M6: 35 | N6: Sports | O6: Smartwatch | P6: Electronics | Q6: Male | R6: 438.62 | S6: Misaligned | T6: 50-64 Boomers | U6: High Value Tier | V6: Stable
A7: ORD5005 | B7: CUST1005 | C7: 46 | D7: PROD205 | E7: Pakistan | F7: 5/16/2023 | G7: 8/13/2025 | H7: 2 | I7: active | J7: 10/14/2024 | K7: $221.61 | L7: 8 | M7: 16 | N7: Electronics | O7: Hoodie | P7: Clothing | Q7: Male | R7: 1772.88 | S7: Misaligned | T7: 35-49 Gen X | U7: High Value Tier | V7: Stable
A8: ORD5006 | B8: CUST1006 | C8: 29 | D8: PROD206 | E8: Germany | F8: 45203 | G8: 7/15/2025 | H8: 1 | I8: active | J8: 45415 | K8: $175.74 | L8: 4 | M8: 7 | N8: Clothing | O8: Tablet | P8: Electronics | Q8: Female | R8: 702.96 | S8: Misaligned | T8: 25-34 Millennials | U8: High Value Tier | V8: Stable
A9: ORD5007 | B9: CUST1007 | C9: 24 | D9: PROD207 | E9: UK | F9: 44872 | G9: 12/31/2024 | H9: 2 | I9: active | J9: 3/21/2025 | K9: $9.56 | L9: 5 | M9: 34 | N9: Clothing | O9: Jacket | P9: Clothing | Q9: Female | R9: 47.8 | S9: Aligned | T9: 18-24 Gen Z | U9: Core Tier | V9: ho
A10: ORD5008 | B10: CUST1008 | C10: 53 | D10: PROD208 | E10: Pakistan | F10: 4/25/2021 | G10: 12/26/2024 | H10: 4 | I10: paused | J10: 12/14/2023 | K10: $1,525.80 | L10: 1 | M10: 32 | N10: Electronics | O10: Nail Polish | P10: Beauty | Q10: Female | R10: 1525.8 | S10: Misaligned | T10: 50-64 Boomers | U10: High Value Tier | V10: Elevated Risk
A11: ORD5009 | B11: CUST1009 | C11: 38 | D11: PROD209 | E11: Germany | F11: 44451 | G11: 11/29/2024 | H11: 2 | I11: active | J11: 12/24/2021 | K11: $337.24 | L11: 4 | M11: 6 | N11: Clothing | O11: Camera | P11: Electronics | Q11: Male | R11: 1348.96 | S11: Misaligned | T11: 35-49 Gen X | U11: High Value Tier | V11: Stable
A12: ORD5010 | B12: CUST1010 | C12: 41 | D12: PROD210 | E12: UK | F12: 43931 | G12: 44600 | H12: 2 | I12: active | J12: 11/23/2023 | K12: $203.05 | L12: 6 | M12: 38 | N12: Home | O12: Dumbbells | P12: Sports | Q12: Female | R12: 1218.3 | S12: Misaligned | T12: 35-49 Gen X | U12: High Value Tier | V12: Stable
A13: ORD5011 | B13: CUST1011 | C13: 24 | D13: PROD211 | E13: Canada | F13: 44897 | G13: 45994 | H13: 1 | I13: active | J13: 5/30/2025 | K13: $940.17 | L13: 1 | M13: 24 | N13: Beauty | O13: Headphones | P13: Electronics | Q13: Female | R13: 940.17 | S13: Misaligned | T13: 18-24 Gen Z | U13: High Value Tier | V13: Stable
A14: ORD5012 | B14: CUST1012 | C14: 39 | D14: PROD212 | E14: Canada | F14: 12/20/2020 | G14: 1/16/2023 | H14: 2 | I14: active | J14: 44385 | K14: $168.79 | L14: 9 | M14: 36 | N14: Beauty | O14: Vacuum Cleaner | P14: Home | Q14: Female | R14: 1519.11 | S14: Misaligned | T14: 35-49 Gen X | U14: High Value Tier | V14: Stable
A15: ORD5013 | B15: CUST1013 | C15: 61 | D15: PROD213 | E15: USA | F15: 2/19/2021 | G15: 45547 | H15: 3 | I15: active | J15: 1/26/2024 | K15: $236.77 | L15: 8 | M15: 5 | N15: Sports | O15: Perfume | P15: Beauty | Q15: Female | R15: 1894.16 | S15: Misaligned | T15: 50-64 Boomers | U15: High Value Tier | V15: Stable
A16: ORD5014 | B16: CUST1014 | C16: 64 | D16: PROD214 | E16: UK | F16: 2/27/2021 | G16: 4/24/2025 | H16: 1 | I16: active | J16: 45089 | K16: $130.32 | L16: 6 | M16: 20 | N16: Clothing | O16: Cycling Helmet | P16: Sports | Q16: Female | R16: 781.92 | S16: Misaligned | T16: 50-64 Boomers | U16: High Value Tier | V16: Stable
A17: ORD5015 | B17: CUST1015 | C17: 28 | D17: PROD215 | E17: UK | F17: 12/31/2021 | G17: 11/15/2023 | H17: 5 | I17: cancelled | J17: 11/30/2024 | K17: $333.99 | L17: 3 | M17: 27 | N17: Home | O17: Face Wash | P17: Beauty | Q17: Female | R17: 1001.97 | S17: Misaligned | T17: 25-34 Millennials | U17: High Value Tier | V17: Stable
A18: ORD5016 | B18: CUST1016 | C18: 34 | D18: PROD216 | E18: USA | F18: 44354 | G18: 45696 | H18: 1 | I18: active | J18: 6/19/2024 | K18: $1,875.08 | L18: 1 | M18: 31 | N18: Sports | O18: Football | P18: Sports | Q18: Female | R18: 1875.08 | S18: Aligned | T18: 25-34 Millennials | U18: High Value Tier | V18: Stable
A19: ORD5017 | B19: CUST1017 | C19: 22 | D19: PROD217 | E19: Pakistan | F19: 9/14/2021 | G19: 45390 | H19: 0 | I19: cancelled | J19: 1/27/2024 | K19: $211.24 | L19: 6 | M19: 18 | N19: Electronics | O19: Cricket Bat | P19: Sports | Q19: Male | R19: 1267.44 | S19: Misaligned | T19: 18-24 Gen Z | U19: High Value Tier | V19: Stable
A20: ORD5018 | B20: CUST1018 | C20: 42 | D20: PROD218 | E20: USA | F20: 5/25/2023 | G20: 45901 | H20: 5 | I20: paused | J20: 8/13/2025 | K20: $1,702.39 | L20: 1 | M20: 14 | N20: Clothing | O20: Sneakers | P20: Clothing | Q20: Male | R20: 1702.39 | S20: Aligned | T20: 35-49 Gen X | U20: High Value Tier | V20: Elevated Risk
A21: ORD5019 | B21: CUST1019 | C21: 51 | D21: PROD219 | E21: India | F21: 9/14/2022 | G21: 8/13/2025 | H21: 0 | I21: paused | J21: 10/27/2024 | K21: $199.58 | L21: 8 | M21: 41 | N21: Clothing | O21: Refrigerator | P21: Home | Q21: Female | R21: 1596.64 | S21: Misaligned | T21: 50-64 Boomers | U21: High Value Tier | V21: Elevated Risk
A22: ORD5020 | B22: CUST1020 | C22: 64 | D22: PROD220 | E22: Canada | F22: 3/13/2022 | G22: 1/23/2024 | H22: 4 | I22: active | J22: 44717 | K22: $242.03 | L22: 6 | M22: 2 | N22: Electronics | O22: Cricket Bat | P22: Sports | Q22: Female | R22: 1452.18 | S22: Misaligned | T22: 50-64 Boomers | U22: High Value Tier | V22: Critical Risk
A23: ORD5021 | B23: CUST1021 | C23: 52 | D23: PROD221 | E23: Germany | F23: 44229 | G23: 6/20/2022 | H23: 1 | I23: paused | J23: 8/20/2024 | K23: $50.78 | L23: 7 | M23: 9 | N23: Home | O23: Dress | P23: Clothing | Q23: Male | R23: 355.46 | S23: Misaligned | T23: 50-64 Boomers | U23: High Value Tier | V23: Elevated Risk
A24: ORD5022 | B24: CUST1022 | C24: 28 | D24: PROD222 | E24: Germany | F24: 44810 | G24: 44689 | H24: 2 | I24: active | J24: 45445 | K24: $89.87 | L24: 6 | M24: 39 | N24: Home | O24: Smartphone | P24: Electronics | Q24: Female | R24: 539.22 | S24: Misaligned | T24: 25-34 Millennials | U24: High Value Tier | V24: Stable
A25: ORD5023 | B25: CUST1023 | C25: 25 | D25: PROD223 | E25: Germany | F25: 44291 | G25: 45967 | H25: 5 | I25: active | J25: 45968 | K25: $52.34 | L25: 8 | M25: 16 | N25: Electronics | O25: Camera | P25: Electronics | Q25: Male | R25: 418.72 | S25: Aligned | T25: 25-34 Millennials | U25: High Value Tier | V25: Critical Risk
A26: ORD5024 | B26: CUST1024 | C26: 45 | D26: PROD224 | E26: Germany | F26: 4/14/2022 | G26: 1/29/2023 | H26: 2 | I26: active | J26: 5/21/2024 | K26: $232.67 | L26: 3 | M26: 20 | N26: Clothing | O26: Lipstick | P26: Beauty | Q26: Male | R26: 698.01 | S26: Misaligned | T26: 35-49 Gen X | U26: High Value Tier | V26: Stable
A27: ORD5025 | B27: CUST1025 | C27: 49 | D27: PROD225 | E27: India | F27: 44388 | G27: 44810 | H27: 3 | I27: cancelled | J27: 9/26/2022 | K27: $142.89 | L27: 5 | M27: 40 | N27: Clothing | O27: Sneakers | P27: Clothing | Q27: Male | R27: 714.45 | S27: Aligned | T27: 35-49 Gen X | U27: High Value Tier | V27: Stable
A28: ORD5026 | B28: CUST1026 | C28: 27 | D28: PROD226 | E28: Germany | F28: 5/15/2023 | G28: 45782 | H28: 0 | I28: paused | J28: 8/26/2024 | K28: $44.69 | L28: 7 | M28: 28 | N28: Beauty | O28: T-Shirt | P28: Clothing | Q28: Male | R28: 312.83 | S28: Misaligned | T28: 25-34 Millennials | U28: High Value Tier | V28: Elevated Risk
A29: ORD5027 | B29: CUST1027 | C29: 69 | D29: PROD227 | E29: Pakistan | F29: 3/23/2021 | G29: 2/25/2022 | H29: 4 | I29: cancelled | J29: 11/13/2024 | K29: $139.30 | L29: 7 | M29: 42 | N29: Clothing | O29: Tennis Racket | P29: Sports | Q29: Male | R29: 975.1 | S29: Misaligned | T29: 65+ Seniors | U29: High Value Tier | V29: Stable
A30: ORD5028 | B30: CUST1028 | C30: 66 | D30: PROD228 | E30: India | F30: 44233 | G30: 45720 | H30: 1 | I30: active | J30: 1/17/2022 | K30: $149.65 | L30: 8 | M30: 45 | N30: Electronics | O30: Sofa | P30: Home | Q30: Male | R30: 1197.2 | S30: Misaligned | T30: 65+ Seniors | U30: High Value Tier | V30: Stable
A31: ORD5029 | B31: CUST1029 | C31: 43 | D31: PROD229 | E31: Canada | F31: 8/22/2020 | G31: 3/22/2024 | H31: 3 | I31: cancelled | J31: 44355 | K31: $157.10 | L31: 6 | M31: 14 | N31: Electronics | O31: Laptop | P31: Electronics | Q31: Female | R31: 942.6 | S31: Aligned | T31: 35-49 Gen X | U31: High Value Tier | V31: Stable
A32: ORD5030 | B32: CUST1030 | C32: 18 | D32: PROD230 | E32: Germany | F32: 4/19/2021 | G32: 44202 | H32: 5 | I32: active | J32: 45019 | K32: $182.53 | L32: 9 | M32: 24 | N32: Clothing | O32: Basketball | P32: Sports | Q32: Male | R32: 1642.77 | S32: Misaligned | T32: 18-24 Gen Z | U32: High Value Tier | V32: Critical Risk
A33: ORD5031 | B33: CUST1031 | C33: 37 | D33: PROD231 | E33: Canada | F33: 8/19/2021 | G33: 7/22/2023 | H33: 4 | I33: paused | J33: 45482 | K33: $31.95 | L33: 1 | M33: 9 | N33: Home | O33: Dress | P33: Clothing | Q33: Male | R33: 31.95 | S33: Misaligned | T33: 35-49 Gen X | U33: Value Tier | V33: Elevated Risk
A34: ORD5032 | B34: CUST1032 | C34: 52 | D34: PROD232 | E34: Germany | F34: 44441 | G34: 7/27/2021 | H34: 0 | I34: cancelled | J34: 45210 | K34: $804.77 | L34: 2 | M34: 26 | N34: Beauty | O34: Cycling Helmet | P34: Sports | Q34: Female | R34: 1609.54 | S34: Misaligned | T34: 50-64 Boomers | U34: High Value Tier | V34: Stable
A35: ORD5033 | B35: CUST1033 | C35: 50 | D35: PROD233 | E35: Canada | F35: 3/25/2022 | G35: 9/25/2022 | H35: 5 | I35: active | J35: 44690 | K35: $332.38 | L35: 5 | M35: 29 | N35: Home | O35: Shirt | P35: Clothing | Q35: Male | R35: 1661.9 | S35: Misaligned | T35: 50-64 Boomers | U35: High Value Tier | V35: Critical Risk
A36: ORD5034 | B36: CUST1034 | C36: 49 | D36: PROD234 | E36: UK | F36: 2/26/2021 | G36: 4/22/2025 | H36: 5 | I36: active | J36: 10/18/2021 | K36: $1,292.65 | L36: 1 | M36: 12 | N36: Electronics | O36: Cricket Bat | P36: Sports | Q36: Female | R36: 1292.65 | S36: Misaligned | T36: 35-49 Gen X | U36: High Value Tier | V36: Critical Risk
A37: ORD5035 | B37: CUST1035 | C37: 48 | D37: PROD235 | E37: India | F37: 44507 | G37: 11/23/2023 | H37: 3 | I37: active | J37: 45357 | K37: $36.39 | L37: 7 | M37: 24 | N37: Electronics | O37: Tablet | P37: Electronics | Q37: Female | R37: 254.73 | S37: Aligned | T37: 35-49 Gen X | U37: High Value Tier | V37: Stable
A38: ORD5036 | B38: CUST1036 | C38: 42 | D38: PROD236 | E38: UK | F38: 44993 | G38: 1/14/2024 | H38: 0 | I38: paused | J38: 9/22/2024 | K38: $79.19 | L38: 7 | M38: 13 | N38: Home | O38: Camera | P38: Electronics | Q38: Male | R38: 554.33 | S38: Misaligned | T38: 35-49 Gen X | U38: High Value Tier | V38: Elevated Risk
A39: ORD5037 | B39: CUST1037 | C39: 66 | D39: PROD237 | E39: India | F39: 3/25/2023 | G39: 5/16/2023 | H39: 3 | I39: active | J39: 12/29/2024 | K39: $94.06 | L39: 4 | M39: 48 | N39: Sports | O39: Blender | P39: Home | Q39: Male | R39: 376.24 | S39: Misaligned | T39: 65+ Seniors | U39: High Value Tier | V39: Stable
A40: ORD5038 | B40: CUST1038 | C40: 25 | D40: PROD238 | E40: Pakistan | F40: 2/17/2022 | G40: 6/29/2023 | H40: 3 | I40: paused | J40: 3/13/2022 | K40: $786.48 | L40: 2 | M40: 11 | N40: Sports | O40: Basketball | P40: Sports | Q40: Female | R40: 1572.96 | S40: Aligned | T40: 25-34 Millennials | U40: High Value Tier | V40: Elevated Risk
...

Sheet KPI Calculation
A1: E-Commerce KPI Calculations — Executive Summary
A2: KPI Metric | B2: Formula Logic | C2: Value | D2: Category | E2: Business Interpretation
A3: Total Gross Revenue | B3: SUM(unit_price × quantity) | C3: =SUM(Table1[gross_revenue]) -> 2051690.7 | D3: Revenue | E3: Total income generated across all orders
A4: Total Orders | B4: COUNT(order_id) | C4: =COUNTA(Table1[customer_id]) -> 2000 | D4: Volume | E4: Total transactions processed
A5: Unique Customers | B5: COUNTUNIQUE(customer_id) | C5: =COUNTA(_xlfn.UNIQUE(Table1[customer_id])) -> 2000 | D5: Customers | E5: Distinct customer base size
A6: Avg Order Value (AOV) | B6: Total Revenue / Total Orders | C6: =AVERAGE(Table1[gross_revenue]) -> 1025.8453 | D6: Revenue | E6: Average spend per transaction
A7: Avg Unit Price | B7: AVERAGE(quantity) | C7: =AVERAGE(Table1[quantity]) -> 4.9485 | D7: Volume | E7: Items per order on average
A8: Avg Quantity / Order | B8: AVERAGE(purchase_frequency) | C8: =AVERAGE(Table1[purchase_frequency]) -> 25.158 | D8: Loyalty | E8: How often customers repurchase
A9: Avg Purchase Frequency | B9: Active / Total Customers | C9: =COUNTIF(Table1[subscription_status], "active") / COUNTA(Table1[subscription_status]) -> 0.602 | D9: Retention | E9: % with active subscription
A10: Active Customer Rate | B10: Cancelled / Total | C10: =COUNTIF(Table1[subscription_status], "cancelled") / COUNTA(Table1[subscription_status]) -> 0.2465 | D10: Churn | E10: % of customers who cancelled
A11: Churn Rate (Cancelled) | B11: Paused / Total | C11: =COUNTIF(Table1[subscription_status], "paused") / COUNTA(Table1[subscription_status]) -> 0.1515 | D11: Churn | E11: % with paused subscription | M11: v
A12: Paused Rate | B12: Aligned / Total Orders | C12: =COUNTIF(Data!S2:S2001, "Aligned") / COUNTA(Data!A2:A2001) -> 0.2085 | D12: Behaviour | E12: Orders matching stated preference
A13: Preference Alignment % | B13: AVERAGE(cancellations_count) | C13: =AVERAGE(Data!H2:H2001) -> 2.4415 | D13: Risk | E13: Avg cancellations per customer
A14: Avg Cancellations / Customer | B14: COUNT(churn_risk='High') | C14: =COUNTIF(Data!V2:V2001, "Critical Risk") -> 388 | D14: Churn | E14: Customers with high churn risk
A15: High Churn Risk Count | B15: MAX by category: Clothing | C15: {=MAX(SUMIF(Data!P2:P2001, Data!P2:P2001, Data!R2:R2001))} -> 439803.15 | D15: Category | E15: Best-performing product category revenue
A16: Revenue - Top Category | B16: MAX by country: Germany | C16: {=MAX(SUMIF(Data!E2:E2001, Data!E2:E2001, Data!R2:R2001))} -> 368249.31 | D16: Geography | E16: Best-performing country revenue
A17: Revenue - Top Country | B17: Female / Total | C17: =COUNTIF(Data!Q2:Q2001, "Female") / COUNTA(Data!Q2:Q2001) -> 0.5075 | D17: Demographics | E17: Share of female customers
A18: Female Customer % | B18: Male / Total | C18: =COUNTIF(Data!Q2:Q2001, "Male") / COUNTA(Data!Q2:Q2001) -> 0.4585 | D18: Demographics | E18: Share of male customers
A19: Male Customer % | B19: MAX(gross_revenue) | C19: =MAX(Data!R2:R2001) -> 1998.08 | D19: Revenue | E19: Highest single-order revenue
A20: Max Revenue Order | B20: SUM(cancellations_count) | C20: =SUM(Data!H2:H2001) -> 4883 | D20: Risk | E20: Total cancellation events across all customers
A21: Total Cancellations

Sheet Pivot Table
A1: Revenue & Orders by Product Category | H1: Subscription Status Analysis
A2: Row Labels | B2: Total_revenue | C2: order_count | D2: Avg_Order_Value | E2: Avg_Unit_Price | H2: Row Labels | I2: Count of customer_id | J2: Sum of gross_revenue | K2: Avg_Cancellations | L2: Avg_Purchase_Freq
A3: Beauty | B3: 405850.74 | C3: 396 | D3: 1024.8756 | E3: 5.0126263 | H3: active | I3: 1204 | J3: 1231160.3 | K3: 2.4393688 | L3: 24.843023
A4: Clothing | B4: 439803.15 | C4: 426 | D4: 1032.4018 | E4: 5.1173709 | H4: cancelled | I4: 493 | J4: 516068.28 | K4: 2.4787018 | L4: 26.06288
A5: Electronics | B5: 411628.81 | C5: 414 | D5: 994.27249 | E5: 4.6908213 | H5: paused | I5: 303 | J5: 304462.11 | K5: 2.3894389 | L5: 24.937294
A6: Home | B6: 392086.74 | C6: 374 | D6: 1048.3603 | E6: 4.8930481 | H6: Grand Total | I6: 2000 | J6: 2051690.7 | K6: 2.4415 | L6: 25.158
A7: Sports | B7: 402321.21 | C7: 390 | D7: 1031.5928 | E7: 5.025641
A8: Grand Total | B8: 2051690.7 | C8: 2000 | D8: 1025.8453 | E8: 4.9485
B9: =SUM(B3:B7) -> 2051690.7 | C9: =SUM(C3:C7) -> 2000 | D9: =AVERAGE(Data!R2:R2001) -> 1025.8453 | H9: Revenue & Behaviour by Age Group
A10: Revenue & Customers by Country | H10: Row Labels | I10: customer_Count | J10: Sum of gross_revenue | K10: Avg_Order_Value | L10: Avg_Purchase_Freq
A11: Row Labels | B11: Total_revenue | C11: order_count | D11: Unique_Customers | E11: Avg_Order_Value | H11: 18-24 Gen Z | I11: 258 | J11: 263546.12 | K11: 1021.4966 | L11: 25.120155
A12: Canada | B12: 321518.32 | C12: 315 | D12: 315 | E12: 1020.6931 | H12: 25-34 Millennials | I12: 345 | J12: 361799.49 | K12: 1048.6942 | L12: 24.930435
A13: Germany | B13: 368249.31 | C13: 360 | D13: 360 | E13: 1022.9148 | H13: 35-49 Gen X | I13: 584 | J13: 598548.38 | K13: 1024.9116 | L13: 25.332192
A14: India | B14: 336791.53 | C14: 324 | D14: 324 | E14: 1039.48 | H14: 50-64 Boomers | I14: 632 | J14: 633398.32 | K14: 1002.2125 | L14: 24.762658
A15: Pakistan | B15: 343162.68 | C15: 332 | D15: 332 | E15: 1033.6225 | H15: 65+ Seniors | I15: 181 | J15: 194398.34 | K15: 1074.024 | L15: 26.464088
A16: UK | B16: 353312.03 | C16: 350 | D16: 350 | E16: 1009.4629 | H16: Grand Total | I16: 2000 | J16: 2051690.7 | K16: 1025.8453 | L16: 25.158
A17: USA | B17: 328656.78 | C17: 319 | D17: 319 | E17: 1030.272
A18: Grand Total | B18: 2051690.7 | C18: 2000 | D18: 2000 | E18: 1025.8453
D19: =SUM(D12:D17) -> 2000 | H19: Revenue by Category × Gender
H20: Sum of gross_revenue | I20: Column Labels
A21: Orders & Revenue by Gender | H21: Row Labels | I21: Female | J21: Male | K21: Other | L21: Grand Total
A22: Row Labels | B22: Order_Count | C22: Total_Revenue | D22: Avg_Order_Value | E22: Avg_Quantity | H22: Beauty | I22: 216591.82 | J22: 169530.34 | K22: 19728.58 | L22: 405850.74
A23: Female | B23: 1015 | C23: 1032432 | D23: 1017.1744 | E23: 4.9891626 | H23: Clothing | I23: 194857.89 | J23: 230559.54 | K23: 14385.72 | L23: 439803.15
A24: Male | B24: 917 | C24: 954161.47 | D24: 1040.525 | E24: 4.9018539 | H24: Electronics | I24: 188809.57 | J24: 214104.17 | K24: 8715.07 | L24: 411628.81
A25: Other | B25: 68 | C25: 65097.18 | D25: 957.31147 | E25: 4.9705882 | H25: Home | I25: 223832.45 | J25: 158138.06 | K25: 10116.23 | L25: 392086.74
A26: total_revenue | C26: 2051690.7 | D26: 2051690.7 | H26: Sports | I26: 208340.27 | J26: 181829.36 | K26: 12151.58 | L26: 402321.21
A27: (blank) | H27: Grand Total | I27: 1032432 | J27: 954161.47 | K27: 65097.18 | L27: 2051690.6
A28: Grand Total | B28: 2000 | C28: 4103381.3 | D28: 2050.6653 | E28: 4.9485
A32: CHURN RATE | B32: =COUNTIF(Table1[subscription_status], "CANCELLED") / ROWS(Table1[]) -> 0.2465 | D32: ACTIVE RATE | E32: =COUNTIF(Table1[subscription_status], "ACTIVE") / ROWS(Table1[]) -> 0.602

Sheet Pivot Charts

Sheet Dashboard
P13: Revenue & Customers by Country
D14: Revenue & Orders by Product Category | J14: Subscription Status Analysis | P14: country | Q14: Total_revenue | R14: order_count | S14: Unique_Customers | T14: Avg_Order_Value
D15: Category | E15: Total_revenue | F15: order_count | G15: Avg_Order_Value | H15: Avg_Unit_Price | J15: Status | K15: Customer count | L15: Sum of gross_revenue | M15: Avg_Cancellations | N15: Avg_Purchase_Freq | P15: ='Pivot Table'!A12 -> Canada | Q15: ='Pivot Table'!B12 -> 321518.32 | R15: ='Pivot Table'!C12 -> 315 | S15: ='Pivot Table'!D12 -> 315 | T15: ='Pivot Table'!E12 -> 1020.6931
D16: ='Pivot Table'!A3 -> Beauty | E16: ='Pivot Table'!B3 -> 405850.74 | F16: ='Pivot Table'!C3 -> 396 | G16: ='Pivot Table'!D3 -> 1024.8756 | H16: ='Pivot Table'!E3 -> 5.0126263 | J16: ='Pivot Table'!H3 -> active | K16: ='Pivot Table'!I3 -> 1204 | L16: ='Pivot Table'!J3 -> 1231160.3 | M16: ='Pivot Table'!K3 -> 2.4393688 | N16: ='Pivot Table'!L3 -> 24.843023 | P16: ='Pivot Table'!A13 -> Germany | Q16: ='Pivot Table'!B13 -> 368249.31 | R16: ='Pivot Table'!C13 -> 360 | S16: ='Pivot Table'!D13 -> 360 | T16: ='Pivot Table'!E13 -> 1022.9148
D17: ='Pivot Table'!A4 -> Clothing | E17: ='Pivot Table'!B4 -> 439803.15 | F17: ='Pivot Table'!C4 -> 426 | G17: ='Pivot Table'!D4 -> 1032.4018 | H17: ='Pivot Table'!E4 -> 5.1173709 | J17: ='Pivot Table'!H4 -> cancelled | K17: ='Pivot Table'!I4 -> 493 | L17: ='Pivot Table'!J4 -> 516068.28 | M17: ='Pivot Table'!K4 -> 2.4787018 | N17: ='Pivot Table'!L4 -> 26.06288 | P17: ='Pivot Table'!A14 -> India | Q17: ='Pivot Table'!B14 -> 336791.53 | R17: ='Pivot Table'!C14 -> 324 | S17: ='Pivot Table'!D14 -> 324 | T17: ='Pivot Table'!E14 -> 1039.48
D18: ='Pivot Table'!A5 -> Electronics | E18: ='Pivot Table'!B5 -> 411628.81 | F18: ='Pivot Table'!C5 -> 414 | G18: ='Pivot Table'!D5 -> 994.27249 | H18: ='Pivot Table'!E5 -> 4.6908213 | J18: ='Pivot Table'!H5 -> paused | K18: ='Pivot Table'!I5 -> 303 | L18: ='Pivot Table'!J5 -> 304462.11 | M18: ='Pivot Table'!K5 -> 2.3894389 | N18: ='Pivot Table'!L5 -> 24.937294 | P18: ='Pivot Table'!A15 -> Pakistan | Q18: ='Pivot Table'!B15 -> 343162.68 | R18: ='Pivot Table'!C15 -> 332 | S18: ='Pivot Table'!D15 -> 332 | T18: ='Pivot Table'!E15 -> 1033.6225
D19: ='Pivot Table'!A6 -> Home | E19: ='Pivot Table'!B6 -> 392086.74 | F19: ='Pivot Table'!C6 -> 374 | G19: ='Pivot Table'!D6 -> 1048.3603 | H19: ='Pivot Table'!E6 -> 4.8930481 | J19: ='Pivot Table'!H6 -> Grand Total | K19: ='Pivot Table'!I6 -> 2000 | L19: ='Pivot Table'!J6 -> 2051690.7 | M19: ='Pivot Table'!K6 -> 2.4415 | N19: ='Pivot Table'!L6 -> 25.158 | P19: ='Pivot Table'!A16 -> UK | Q19: ='Pivot Table'!B16 -> 353312.03 | R19: ='Pivot Table'!C16 -> 350 | S19: ='Pivot Table'!D16 -> 350 | T19: ='Pivot Table'!E16 -> 1009.4629
D20: ='Pivot Table'!A7 -> Sports | E20: ='Pivot Table'!B7 -> 402321.21 | F20: ='Pivot Table'!C7 -> 390 | G20: ='Pivot Table'!D7 -> 1031.5928 | H20: ='Pivot Table'!E7 -> 5.025641 | P20: ='Pivot Table'!A17 -> USA | Q20: ='Pivot Table'!B17 -> 328656.78 | R20: ='Pivot Table'!C17 -> 319 | S20: ='Pivot Table'!D17 -> 319 | T20: ='Pivot Table'!E17 -> 1030.272
D21: ='Pivot Table'!A8 -> Grand Total | E21: ='Pivot Table'!B8 -> 2051690.7 | F21: ='Pivot Table'!C8 -> 2000 | G21: ='Pivot Table'!D8 -> 1025.8453 | H21: ='Pivot Table'!E8 -> 4.9485 | P21: ='Pivot Table'!A18 -> Grand Total | Q21: ='Pivot Table'!B18 -> 2051690.7 | R21: ='Pivot Table'!C18 -> 2000 | S21: ='Pivot Table'!D18 -> 2000 | T21: ='Pivot Table'!E18 -> 1025.8453
B24: Revenue by Product Category | I24: Subscription Status Breakdown | N24: Revenue Distribution by Country
C46: Revenue & Behaviour by Age Group | I46: Orders & Revenue by Gender | O46: Revenue by Category × Gender
C47: Age group | D47: customer_Count | E47: Sum of gross_revenue | F47: Avg_Order_Value | G47: Avg_Purchase_Freq | I47: Gender | J47: Order_Count | K47: Total_Revenue | L47: Avg_Order_Value | M47: Avg_Quantity | O47: Gender | P47: Female | Q47: Male | R47: Other | S47: Grand Total
C48: ='Pivot Table'!H11 -> 18-24 Gen Z | D48: ='Pivot Table'!I11 -> 258 | E48: ='Pivot Table'!J11 -> 263546.12 | F48: ='Pivot Table'!K11 -> 1021.4966 | G48: ='Pivot Table'!L11 -> 25.120155 | I48: ='Pivot Table'!A23 -> Female | J48: ='Pivot Table'!B23 -> 1015 | K48: ='Pivot Table'!C23 -> 1032432 | L48: ='Pivot Table'!D23 -> 1017.1744 | M48: ='Pivot Table'!E23 -> 4.9891626 | O48: ='Pivot Table'!H22 -> Beauty | P48: ='Pivot Table'!I22 -> 216591.82 | Q48: ='Pivot Table'!J22 -> 169530.34 | R48: ='Pivot Table'!K22 -> 19728.58 | S48: ='Pivot Table'!L22 -> 405850.74
C49: ='Pivot Table'!H12 -> 25-34 Millennials | D49: ='Pivot Table'!I12 -> 345 | E49: ='Pivot Table'!J12 -> 361799.49 | F49: ='Pivot Table'!K12 -> 1048.6942 | G49: ='Pivot Table'!L12 -> 24.930435 | I49: ='Pivot Table'!A24 -> Male | J49: ='Pivot Table'!B24 -> 917 | K49: ='Pivot Table'!C24 -> 954161.47 | L49: ='Pivot Table'!D24 -> 1040.525 | M49: ='Pivot Table'!E24 -> 4.9018539 | O49: ='Pivot Table'!H23 -> Clothing | P49: ='Pivot Table'!I23 -> 194857.89 | Q49: ='Pivot Table'!J23 -> 230559.54 | R49: ='Pivot Table'!K23 -> 14385.72 | S49: ='Pivot Table'!L23 -> 439803.15
C50: ='Pivot Table'!H13 -> 35-49 Gen X | D50: ='Pivot Table'!I13 -> 584 | E50: ='Pivot Table'!J13 -> 598548.38 | F50: ='Pivot Table'!K13 -> 1024.9116 | G50: ='Pivot Table'!L13 -> 25.332192 | I50: ='Pivot Table'!A25 -> Other | J50: ='Pivot Table'!B25 -> 68 | K50: ='Pivot Table'!C25 -> 65097.18 | L50: ='Pivot Table'!D25 -> 957.31147 | M50: ='Pivot Table'!E25 -> 4.9705882 | O50: ='Pivot Table'!H24 -> Electronics | P50: ='Pivot Table'!I24 -> 188809.57 | Q50: ='Pivot Table'!J24 -> 214104.17 | R50: ='Pivot Table'!K24 -> 8715.07 | S50: ='Pivot Table'!L24 -> 411628.81
C51: ='Pivot Table'!H14 -> 50-64 Boomers | D51: ='Pivot Table'!I14 -> 632 | E51: ='Pivot Table'!J14 -> 633398.32 | F51: ='Pivot Table'!K14 -> 1002.2125 | G51: ='Pivot Table'!L14 -> 24.762658 | I51: ='Pivot Table'!A26 -> total_revenue | J51: ='Pivot Table'!B26 -> 0 | K51: ='Pivot Table'!C26 -> 2051690.7 | L51: ='Pivot Table'!D26 -> 2051690.7 | M51: ='Pivot Table'!E26 -> 0 | O51: ='Pivot Table'!H25 -> Home | P51: ='Pivot Table'!I25 -> 223832.45 | Q51: ='Pivot Table'!J25 -> 158138.06 | R51: ='Pivot Table'!K25 -> 10116.23 | S51: ='Pivot Table'!L25 -> 392086.74
C52: ='Pivot Table'!H15 -> 65+ Seniors | D52: ='Pivot Table'!I15 -> 181 | E52: ='Pivot Table'!J15 -> 194398.34 | F52: ='Pivot Table'!K15 -> 1074.024 | G52: ='Pivot Table'!L15 -> 26.464088 | I52: ='Pivot Table'!A27 -> (blank) | J52: ='Pivot Table'!B27 -> 0 | K52: ='Pivot Table'!C27 -> 0 | L52: ='Pivot Table'!D27 -> 0 | M52: ='Pivot Table'!E27 -> 0 | O52: ='Pivot Table'!H26 -> Sports | P52: ='Pivot Table'!I26 -> 208340.27 | Q52: ='Pivot Table'!J26 -> 181829.36 | R52: ='Pivot Table'!K26 -> 12151.58 | S52: ='Pivot Table'!L26 -> 402321.21
C53: ='Pivot Table'!H16 -> Grand Total | D53: ='Pivot Table'!I16 -> 2000 | E53: ='Pivot Table'!J16 -> 2051690.7 | F53: ='Pivot Table'!K16 -> 1025.8453 | G53: ='Pivot Table'!L16 -> 25.158 | I53: ='Pivot Table'!A28 -> Grand Total | J53: ='Pivot Table'!B28 -> 2000 | K53: ='Pivot Table'!C28 -> 4103381.3 | L53: ='Pivot Table'!D28 -> 2050.6653 | M53: ='Pivot Table'!E28 -> 4.9485 | O53: ='Pivot Table'!H27 -> Grand Total | P53: ='Pivot Table'!I27 -> 1032432 | Q53: ='Pivot Table'!J27 -> 954161.47 | R53: ='Pivot Table'!K27 -> 65097.18 | S53: ='Pivot Table'!L27 -> 2051690.6
C56: Revenue & Behaviour by Age Group | I56: Orders & Revenue by Gender | O56: Revenue by Category × Gender
